Workbook
Name Absa_Group_Limited: BACKROOM2_TEB!$H$19
Name AlibabaGroup: BACKROOM2_TEB!$AO$19
Name Amazon: BACKROOM2_TEB!$O$19
Name AngloAmerican: BACKROOM2_TEB!$E$19
Name Apple: BACKROOM2_TEB!$N$19
Name BancodoBrasil: BACKROOM2_TEB!$AK$19
Name BM: BACKROOM2_TEB!$P$2:$P$12
Name BMW: BACKROOM2_TEB!$L$19
Name BP: BACKROOM2_TEB!$AV$19
Name br_countries: #REF!
Name Brazil: BACKROOM2_TEB!$F$2:$F$12
Name BritishAmericanTobacco: BACKROOM2_TEB!$AX$19
Name chi_countries: #REF!
Name China: BACKROOM2_TEB!$G$2:$G$12
Name ChinaConstructionBank: BACKROOM2_TEB!$AR$19
Name CiscoSystems: BACKROOM2_TEB!$V$19
Name CompanyList: TEB!$P$2:$P$51
Name CountryList: TEB!$O$2:$O$51
Name Dell: BACKROOM2_TEB!$W$19
Name DiscoveryLimited: BACKROOM2_TEB!$F$19
Name EskomHoldings: BACKROOM2_TEB!$K$19
Name ExchangeList: TEB!$Q$2:$Q$51
Name Facebook: BACKROOM2_TEB!$P$19
Name FirstRandLimited: BACKROOM2_TEB!$I$19
Name FSE: BACKROOM2_TEB!$L$2:$L$12
Name Gazprom: BACKROOM2_TEB!$AE$19
Name Germany: BACKROOM2_TEB!$B$2:$B$12
Name GlaxoSmithKline: BACKROOM2_TEB!$AW$19
Name gm_countries: #REF!
Name Google: BACKROOM2_TEB!$Q$19
Name Honda: BACKROOM2_TEB!$AC$19
Name HP: BACKROOM2_TEB!$X$19
Name HSBCHoldings: BACKROOM2_TEB!$AT$19
Name Huawei: BACKROOM2_TEB!$AQ$19
Name Industrial_CommercialBankofChina: BACKROOM2_TEB!$AS$19
Name Intel: BACKROOM2_TEB!$R$19
Name ItaúUnibanco: BACKROOM2_TEB!$AL$19
Name Japan: BACKROOM2_TEB!$D$2:$D$12
Name JBS: BACKROOM2_TEB!$AN$19
Name jpn_countries: #REF!
Name JSE: BACKROOM2_TEB!$K$2:$K$12
Name Konami: BACKROOM2_TEB!$AA$19
Name LSE: BACKROOM2_TEB!$R$2:$R$12
Name Lukoil: BACKROOM2_TEB!$AG$19
Name MercedesBenz: BACKROOM2_TEB!$M$19
Name Microsoft: BACKROOM2_TEB!$S$19
Name MOEX: BACKROOM2_TEB!$O$2:$O$12
Name MTN_Group: BACKROOM2_TEB!$B$19
Name Nasdaq: BACKROOM2_TEB!$M$2:$M$12
Name Naspers: BACKROOM2_TEB!$A$19
Name Nissan: BACKROOM2_TEB!$Z$19
Name Oracle: BACKROOM2_TEB!$T$19
Name Petrobras: BACKROOM2_TEB!$AJ$19
Name RateList: TEB!$R$2:$R$51
Name Rosneft: BACKROOM2_TEB!$AF$19
Name Rostelecom: BACKROOM2_TEB!$AI$19
Name rus_countries: #REF!
Name Russia: BACKROOM2_TEB!$E$2:$E$12
Name Sanlam: BACKROOM2_TEB!$J$19
Name Sasol: BACKROOM2_TEB!$C$19

Sheet HOME

Sheet 1. RATE CONVERTER
O10: From | Q10: To
O11: Interest | P11: 0.08
O12: Period | P12: 4 | Q12: Period | R12: 1
O13: Type | P13: effective annual | Q13: Type | R13: Nominal
O14: Years | P14: 6 | Q14: Years | R14: 6
O16: CONVERTED RAATE
O17: =IF(AND(P13=BACKROOM1!A8,R13=BACKROOM1!B7),BACKROOM1!B8,IF(AND(P13=BACKROOM1!A8,R13=BACKROOM1!C7),BACKROOM1!C8,IF(AND(P13=BACKROOM1!A8,R13=BACKROOM1!D7),BACKROOM1!D8,IF(AND(P13=BACKROOM1!A8,R13=BACKROOM1!E7),BACKROOM1!E8,IF(AND(P13=BACKROOM1!A9,R13=BACKROOM1!B7),BACKROOM1!B9,IF(AND(P13=BACKROOM1!A9,R13=BACKROOM1!C7),BACKROOM1!C9,IF(AND(P13=BACKROOM1!A9,R13=BACKROOM1!D7),BACKROOM1!D9,IF(AND(P13=BACKROOM1!A9,R13=BACKROOM1!E7),BACKROOM1!E9,IF(AND(P13=BACKROOM1!A10,R13=BACKROOM1!B7),BACKROOM1!B10,IF(AND(P13=BACKROOM1!A10,R13=BACKROOM1!C7),BACKROOM1!C10,IF(AND(P13=BACKROOM1!A10,R13=BACKROOM1!D7),BACKROOM1!D10,IF(AND(P13=BACKROOM1!A10,R13=BACKROOM1!E7),BACKROOM1!E10,IF(AND(P13=BACKROOM1!A11,R13=BACKROOM1!B7),BACKROOM1!B11,IF(AND(P13=BACKROOM1!A11,R13=BACKROOM1!C7),BACKROOM1!C11,IF(AND(P13=BACKROOM1!A11,R13=BACKROOM1!D7),BACKROOM1!D11,IF(AND(P13=BACKROOM1!A11,R13=BACKROOM1!E7),BACKROOM1!E11,IF(AND(P13=BACKROOM1!A12,R13=BACKROOM1!B7),BACKROOM1!B12,IF(AND(P13=BACKROOM1!A12,R13=BACKROOM1!C7),BACKROOM1!C12,IF(AND(P13=BACKROOM1!A12,R13=BACKROOM1!D7),BACKROOM1!D12,IF(AND(P13=BACKROOM1!A12,R13=BACKROOM1!E7),BACKROOM1!E12,IF(AND(P13=BACKROOM1!A8,R13=BACKROOM1!F7),BACKROOM1!F8,IF(AND(P13=BACKROOM1!A9,R13=BACKROOM1!F7),BACKROOM1!F9,IF(AND(P13=BACKROOM1!A10,R13=BACKROOM1!F7),BACKROOM1!F10,IF(AND(P13=BACKROOM1!A11,R13=BACKROOM1!F7),BACKROOM1!F11,"ERROR")))))))))))))))))))))))) -> 0.08

Sheet 2. SINGLE INVESTMENTS
Y2: GIVEN
Y3: FV | Z3: =K6 -> 10000
B4: NUMBER OF YEARS | Y4: PV | Z4: =K7 -> 2000
B5: DATE(START): | C5: =DATE(C7, C6,C8) -> 40204 | D5: DATE(END): | E5: =DATE(E7,E6,E8) -> 45419 | J5: INPUT | Y5: i(p)/p | Z5: =K8 -> 0.1
B6: MONTH: | C6: 1 | D6: MONTH: | E6: 5 | J6: FUTURE VALUE | K6: 10000 | Y6: N | Z6: =K9 -> 10
B7: YEAR: | C7: 2010 | D7: YEAR: | E7: 2024 | J7: PRESENT VALUE | K7: 2000 | Y7: P | Z7: =K10 -> 8
B8: DAY: | C8: 26 | D8: DAY: | E8: 7 | J8: INTEREST RATE | K8: 0.1
B9: NUMBER OF YEARS | E9: =(E5-C5)/365 -> 14.287671 | J9: YEARS | K9: 10
B10: YEARS(GIVEN) | E10: 10 | J10: PERIODS | K10: 8
J11: INTEREST WITH NO CONVERSION | K11: 0.1
J12: TYPE OF OUTCOME
B13: From | D13: To | J13: OUTPUT | K13: FUTURE VALUE | AO13: Coumpound | AR13: Simple
B14: Interest | C14: 0.07 | J14: TYPE | K14: SIMPLE | AO14: Period | AP14: Future Value | AR14: Period | AS14: Future Value
B15: Period | C15: 12 | D15: Period | E15: 4 | J15: OUTPUT | AO15: 1 | AP15: =('[1]From SI'!$D4*(1+'[1]From SI'!$D5)^('[1]From SI'!$D6*AO15)) -> 890.21637 | AR15: 1 | AS15: =Z4*(1+Z5*Z6*AR15) -> 4000
B16: Type | C16: effective periodic | D16: Type | E16: Effective periodic | J16: ANSWER: | K16: =IF(AND(K13=BACKROOM1!L23,K14=BACKROOM1!K24),BACKROOM1!L24,IF(AND(K13=BACKROOM1!M23,K14=BACKROOM1!K24),BACKROOM1!M24,IF(AND(K13=BACKROOM1!P23,K14=BACKROOM1!K24),BACKROOM1!P24,IF(AND(K13=BACKROOM1!L23,K14=BACKROOM1!K25),BACKROOM1!L25,IF(AND(K13=BACKROOM1!M23,K14=BACKROOM1!K25),BACKROOM1!M25,IF(AND(K13=BACKROOM1!P23,K14=BACKROOM1!K25),BACKROOM1!P25,IF(AND(K13=BACKROOM1!L23,K14=BACKROOM1!K26),BACKROOM1!L26,IF(AND(K13=BACKROOM1!M23,K14=BACKROOM1!K26),BACKROOM1!M26,IF(AND(K13=BACKROOM1!P23,K14=BACKROOM1!K26),BACKROOM1!P26,IF(AND(K13=BACKROOM1!L23,K14=BACKROOM1!K27),BACKROOM1!L27,IF(AND(K13=BACKROOM1!M23,K14=BACKROOM1!K27),BACKROOM1!M27,IF(AND(K13=BACKROOM1!P23,K14=BACKROOM1!K27),BACKROOM1!P27,IF(AND(K13=BACKROOM1!L23,K14=BACKROOM1!K28),BACKROOM1!L28,IF(AND(K13=BACKROOM1!M23,K14=BACKROOM1!K28),BACKROOM1!M28,IF(AND(K13=BACKROOM1!P23,K14=BACKROOM1!K28),BACKROOM1!P28,"-"))))))))))))))) -> 18000 | AO16: 2 | AP16: =('[1]From SI'!$D4*(1+'[1]From SI'!$D5)^('[1]From SI'!$D6*AO16)) -> 1981.213 | AR16: 2 | AS16: =Z4*(1+Z5*Z6*AR16) -> 6000
B17: Years | C17: 1 | D17: Years | E17: 1 | J17: PERIOD VALUE: | K17: =IF(AND(K13=BACKROOM1!N23,K14=BACKROOM1!K24),BACKROOM1!N24,IF(AND(K13=BACKROOM1!N23,K14=BACKROOM1!K25),BACKROOM1!N25,IF(AND(K13=BACKROOM1!N23,K14=BACKROOM1!K26),BACKROOM1!N26,IF(AND(K13=BACKROOM1!N23,K14=BACKROOM1!K27),BACKROOM1!N27,IF(AND(K13=BACKROOM1!N23,K14=BACKROOM1!K28),BACKROOM1!N28,"-"))))) -> - | AO17: 3 | AP17: =('[1]From SI'!$D4*(1+'[1]From SI'!$D5)^('[1]From SI'!$D6*AO17)) -> 4409.2706 | AR17: 3 | AS17: =Z4*(1+Z5*Z6*AR17) -> 8000
J18: RATE (%): | K18: =IF(AND(K13=BACKROOM1!O23,K14=BACKROOM1!K24),BACKROOM1!O24,IF(AND(K13=BACKROOM1!O23,K14=BACKROOM1!K25),BACKROOM1!O25,IF(AND(K13=BACKROOM1!O23,K14=BACKROOM1!K26),BACKROOM1!O26,IF(AND(K13=BACKROOM1!O23,K14=BACKROOM1!K27),BACKROOM1!O27,IF(AND(K13=BACKROOM1!O23,K14=BACKROOM1!K28),BACKROOM1!O28,"-"))))) -> - | AO18: 4 | AP18: =('[1]From SI'!$D4*(1+'[1]From SI'!$D5)^('[1]From SI'!$D6*AO18)) -> 9813.0121 | AR18: 4 | AS18: =Z4*(1+Z5*Z6*AR18) -> 10000
B19: RATE | E19: =IF(AND(C16=BACKROOM1!K11,E16=BACKROOM1!L10),BACKROOM1!L11,IF(AND(C16=BACKROOM1!K11,E16=BACKROOM1!M10),BACKROOM1!M11,IF(AND(C16=BACKROOM1!K11,E16=BACKROOM1!N10),BACKROOM1!N11,IF(AND(C16=BACKROOM1!K11,E16=BACKROOM1!O10),BACKROOM1!O11,IF(AND(C16=BACKROOM1!K12,E16=BACKROOM1!L10),BACKROOM1!L12,IF(AND(C16=BACKROOM1!K12,E16=BACKROOM1!M10),BACKROOM1!M12,IF(AND(C16=BACKROOM1!K12,E16=BACKROOM1!N10),BACKROOM1!N12,IF(AND(C16=BACKROOM1!K12,E16=BACKROOM1!O10),BACKROOM1!O12,IF(AND(C16=BACKROOM1!K13,E16=BACKROOM1!L10),BACKROOM1!L13,IF(AND(C16=BACKROOM1!K13,E16=BACKROOM1!M10),BACKROOM1!M13,IF(AND(C16=BACKROOM1!K13,E16=BACKROOM1!N10),BACKROOM1!N13,IF(AND(C16=BACKROOM1!K13,E16=BACKROOM1!O10),BACKROOM1!O13,IF(AND(C16=BACKROOM1!K14,E16=BACKROOM1!L10),BACKROOM1!L14,IF(AND(C16=BACKROOM1!K14,E16=BACKROOM1!M10),BACKROOM1!M14,IF(AND(C16=BACKROOM1!K14,E16=BACKROOM1!N10),BACKROOM1!N14,IF(AND(C16=BACKROOM1!K14,E16=BACKROOM1!O10),BACKROOM1!O14,IF(AND(C16=BACKROOM1!K15,E16=BACKROOM1!L10),BACKROOM1!L15,IF(AND(C16=BACKROOM1!K15,E16=BACKROOM1!M10),BACKROOM1!M15,IF(AND(C16=BACKROOM1!K15,E16=BACKROOM1!N10),BACKROOM1!N15,IF(AND(C16=BACKROOM1!K15,E16=BACKROOM1!O10),BACKROOM1!O15,IF(AND(C16=BACKROOM1!K11,E16=BACKROOM1!P10),BACKROOM1!P11,IF(AND(C16=BACKROOM1!K12,E16=BACKROOM1!P10),BACKROOM1!P12,IF(AND(C16=BACKROOM1!K13,E16=BACKROOM1!P10),BACKROOM1!P13,IF(AND(C16=BACKROOM1!K14,E16=BACKROOM1!P10),BACKROOM1!P14,"ERROR")))))))))))))))))))))))) -> 0.225043 | AO19: 5 | AP19: =('[1]From SI'!$D4*(1+'[1]From SI'!$D5)^('[1]From SI'!$D6*AO19)) -> 21839.26 | AR19: 5 | AS19: =Z4*(1+Z5*Z6*AR19) -> 12000
AO20: 6 | AP20: =('[1]From SI'!$D4*(1+'[1]From SI'!$D5)^('[1]From SI'!$D6*AO20)) -> 48604.167 | AR20: 6 | AS20: =Z4*(1+Z5*Z6*AR20) -> 14000
AO21: 7 | AP21: =('[1]From SI'!$D4*(1+'[1]From SI'!$D5)^('[1]From SI'!$D6*AO21)) -> 108170.56 | AR21: 7 | AS21: =Z4*(1+Z5*Z6*AR21) -> 16000
AO22: 8 | AP22: =('[1]From SI'!$D4*(1+'[1]From SI'!$D5)^('[1]From SI'!$D6*AO22)) -> 240738.02 | AR22: 8 | AS22: =Z4*(1+Z5*Z6*AR22) -> 18000
AO23: 9 | AP23: =('[1]From SI'!$D4*(1+'[1]From SI'!$D5)^('[1]From SI'!$D6*AO23)) -> 535772.31 | AR23: 9 | AS23: =Z4*(1+Z5*Z6*AR23) -> 20000
AO24: 10 | AP24: =('[1]From SI'!$D4*(1+'[1]From SI'!$D5)^('[1]From SI'!$D6*AO24)) -> 1192383.2 | AR24: 10 | AS24: =Z4*(1+Z5*Z6*AR24) -> 22000

Sheet 3. ANNUITIES
I4: NUMBER OF YEARS
I5: DATE(START): | J5: =DATE(J7, J6,J8) -> 40204 | K5: DATE(END): | L5: =DATE(L7,L6,L8) -> 45419
I6: MONTH: | J6: 1 | K6: MONTH: | L6: 5 | O6: Given
I7: YEAR: | J7: 2010 | K7: YEAR: | L7: 2024 | O7: INSTALLMENT: | Q7: 5000
I8: DAY: | J8: 26 | K8: DAY: | L8: 7 | O8: INTEREST RATE: | Q8: 0.02020134
I9: NUMBER OF YEARS | L9: =(L5-J5)/365 -> 14.287671 | O9: NUMBER OF YEARS: | Q9: 5
I10: YEARS(GIVEN) | L10: 5 | O10: PERIOD: | Q10: 12
O11: PRESENT VALUE: | Q11: 5200
I12: From | K12: To | O12: FUTURE VALUE: | Q12: 6600
I13: Interest | J13: 0.08 | O13: INTEREST WITH NO CONVERSION | Q13: 0.07
I14: Period | J14: 1 | K14: Period | L14: =Q10 -> 12
I15: Type | J15: continous | K15: Type | L15: Effective annual
I16: Years | J16: 1 | K16: Years | L16: 1
I17: RATE | L17: =IF(AND(J15=BACKROOM1!Y14,L15=BACKROOM1!Z13),BACKROOM1!Z14,IF(AND(J15=BACKROOM1!Y14,L15=BACKROOM1!AA13),BACKROOM1!AA14,IF(AND(J15=BACKROOM1!Y14,L15=BACKROOM1!AB13),BACKROOM1!AB14,IF(AND(J15=BACKROOM1!Y14,L15=BACKROOM1!AC13),BACKROOM1!AC14,IF(AND(J15=BACKROOM1!Y15,L15=BACKROOM1!Z13),BACKROOM1!Z15,IF(AND(J15=BACKROOM1!Y15,L15=BACKROOM1!AA13),BACKROOM1!AA15,IF(AND(J15=BACKROOM1!Y15,L15=BACKROOM1!AB13),BACKROOM1!AB15,IF(AND(J15=BACKROOM1!Y15,L15=BACKROOM1!AC13),BACKROOM1!AC15,IF(AND(J15=BACKROOM1!Y16,L15=BACKROOM1!Z13),BACKROOM1!Z16,IF(AND(J15=BACKROOM1!Y16,L15=BACKROOM1!AA13),BACKROOM1!AA16,IF(AND(J15=BACKROOM1!Y16,L15=BACKROOM1!AB13),BACKROOM1!AB16,IF(AND(J15=BACKROOM1!Y16,L15=BACKROOM1!AC13),BACKROOM1!AC16,IF(AND(J15=BACKROOM1!Y17,L15=BACKROOM1!Z13),BACKROOM1!Z17,IF(AND(J15=BACKROOM1!Y17,L15=BACKROOM1!AA13),BACKROOM1!AA17,IF(AND(J15=BACKROOM1!Y17,L15=BACKROOM1!AB13),BACKROOM1!AB17,IF(AND(J15=BACKROOM1!Y17,L15=BACKROOM1!AC13),BACKROOM1!AC17,IF(AND(J15=BACKROOM1!Y18,L15=BACKROOM1!Z13),BACKROOM1!Z18,IF(AND(J15=BACKROOM1!Y18,L15=BACKROOM1!AA13),BACKROOM1!AA18,IF(AND(J15=BACKROOM1!Y18,L15=BACKROOM1!AB13),BACKROOM1!AB18,IF(AND(J15=BACKROOM1!Y18,L15=BACKROOM1!AC13),BACKROOM1!AC18,IF(AND(J15=BACKROOM1!Y14,L15=BACKROOM1!AD13),BACKROOM1!AD14,IF(AND(J15=BACKROOM1!Y15,L15=BACKROOM1!AD13),BACKROOM1!AD15,IF(AND(J15=BACKROOM1!Y16,L15=BACKROOM1!AD13),BACKROOM1!AD16,IF(AND(J15=BACKROOM1!Y17,L15=BACKROOM1!AD13),BACKROOM1!AD17,"ERROR")))))))))))))))))))))))) -> 0.0066889384
N23: OUTPUT IN ARREARS | Q23: OUTPUT IN ADVANCE
N24: FUTURE VALUE | P24: =((Q7*(1+Q8)^(Q9*Q10)-1)/Q8) -> 821707.1 | Q24: FUTURE VALUE: | R24: =(Q7*(1+Q8)*((1+Q8)^(Q9*Q10)-1))/Q8 -> 585848.86
N25: PRESENT VALUE | P25: =((Q7*(1-(1+Q8)^(-Q9*Q10)))/Q8) -> 172960.26 | Q25: PRESENT VALUE: | R25: =(Q7*(1+Q8)*(1-(1+Q8)^(-Q9*Q10)))/Q8 -> 176454.28
N26: YEARS(FV) | P26: =(LOG(BACKROOM1!V28,(1+Q8)))/Q10 -> 0.10965181 | Q26: NUMBER OF YEARS(FV): | R26: =(LOG(BACKROOM1!U12,(1+Q8)))/Q10 -> 0.11183745
N27: YEARS(PV) | P27: =(LOG(BACKROOM1!U25,(1/(1+Q8))))/Q10 -> 0.088471798 | Q27: NUMBER OF YEARS(PV): | R27: =(LOG(BACKROOM1!U13,(1/(1+Q8))))/Q10 -> 0.090278549
N28: INSTALLMENT(FV) | P28: =((Q12*Q8)/((1+Q8)^(Q9*Q10)-1)) -> 57.466433 | Q28: INSTALLMENT(FV): | R28: =((Q12*Q8)/((1+Q8)*((1+Q8)^(Q9*Q10)-1))) -> 56.328522
N29: INSTALLMENT(PV) | P29: =((Q11*Q8)/(1-(1+Q8)^(BACKROOM1!V25))) -> 150.32355 | Q29: INSTALLMENT(PV): | R29: =((Q11*Q8)/((1+Q8)*(1-(1+Q8)^(-Q9*Q10)))) -> 147.34695
N30: INTEREST(FV) | P30: =((Q7*(1+Q8)^(Q9*Q10)-1)/(Q12)) -> 2.5150886 | Q30: INTEREST(FV) | R30: =(Q7*(1+Q8)*((1+Q8)^(Q9*Q10)-1))/Q12 -> 1.7931715
N31: INTEREST(PV) | P31: =((Q7*(1-(1+Q8)^(BACKROOM1!V25)))/Q11) -> 0.67192864 | Q31: INTEREST(PV) | R31: =(Q7*(1+Q8)*(1-(1+Q8)^(-Q9*Q10)))/Q11 -> 0.6855025

Sheet 4.LOANS
G3: NUMBER OF YEARS
G4: DATE(START): | H4: =DATE(H6, H5,H7) -> 42019 | I4: DATE(END): | J4: =DATE(J6,J5,J7) -> 44841
G5: MONTH: | H5: 1 | I5: MONTH: | J5: 10
G6: YEAR: | H6: 2015 | I6: YEAR: | J6: 2022
G7: DAY: | H7: 15 | I7: DAY: | J7: 7
G8: NUMBER OF YEARS | J8: =(J4-H4)/365 -> 7.7315068
G9: YEARS(GIVEN) | J9: 5
O10: INPUTS
G11: FROM | I11: TO | O11: Loan Amount: | R11: 250000
O12: Installment: | R12: 10000
G13: Interest | H13: 0.06 | O13: Number of Years: | R13: 7.7315068
G14: Period | H14: 4 | I14: Period | J14: ='4.LOANS'!R15 -> 2 | O14: Interest: | R14: 0.06
G15: Type | H15: nominal | I15: Type | J15: Effective periodic | O15: Period): | R15: 2
G16: Years | H16: 6 | I16: Years | J16: 6 | O16: During Period: | R16: 2
G17: RATE | J17: =IF(AND(H15=BACKROOM1!AK28,J15=BACKROOM1!AL27),BACKROOM1!AL28,IF(AND(H15=BACKROOM1!AK28,J15=BACKROOM1!AM27),BACKROOM1!AM28,IF(AND(H15=BACKROOM1!AK28,J15=BACKROOM1!AN27),BACKROOM1!AN28,IF(AND(H15=BACKROOM1!AK28,J15=BACKROOM1!AO27),BACKROOM1!AO28,IF(AND(H15=BACKROOM1!AK29,J15=BACKROOM1!AL27),BACKROOM1!AL29,IF(AND(H15=BACKROOM1!AK29,J15=BACKROOM1!AM27),BACKROOM1!AM29,IF(AND(H15=BACKROOM1!AK29,J15=BACKROOM1!AN27),BACKROOM1!AN29,IF(AND(H15=BACKROOM1!AK29,J15=BACKROOM1!AO27),BACKROOM1!AO29,IF(AND(H15=BACKROOM1!AK30,J15=BACKROOM1!AL27),BACKROOM1!AL30,IF(AND(H15=BACKROOM1!AK30,J15=BACKROOM1!AM27),BACKROOM1!AM30,IF(AND(H15=BACKROOM1!AK30,J15=BACKROOM1!AN27),BACKROOM1!AN30,IF(AND(H15=BACKROOM1!AK30,J15=BACKROOM1!AO27),BACKROOM1!AO30,IF(AND(H15=BACKROOM1!AK31,J15=BACKROOM1!AL27),BACKROOM1!AL31,IF(AND(H15=BACKROOM1!AK31,J15=BACKROOM1!AM27),BACKROOM1!AM31,IF(AND(H15=BACKROOM1!AK31,J15=BACKROOM1!AN27),BACKROOM1!AN31,IF(AND(H15=BACKROOM1!AK31,J15=BACKROOM1!AO27),BACKROOM1!AO31,IF(AND(H15=BACKROOM1!AK32,J15=BACKROOM1!AL27),BACKROOM1!AL32,IF(AND(H15=BACKROOM1!AK32,J15=BACKROOM1!AM27),BACKROOM1!AM32,IF(AND(H15=BACKROOM1!AK32,J15=BACKROOM1!AN27),BACKROOM1!AN32,IF(AND(H15=BACKROOM1!AK32,J15=BACKROOM1!AO27),BACKROOM1!AO32,IF(AND(H15=BACKROOM1!AK28,J15=BACKROOM1!AP27),BACKROOM1!AP28,IF(AND(H15=BACKROOM1!AK29,J15=BACKROOM1!AP27),BACKROOM1!AP29,IF(AND(H15=BACKROOM1!AK30,J15=BACKROOM1!AP27),BACKROOM1!AP30,IF(AND(H15=BACKROOM1!AK31,J15=BACKROOM1!AP27),BACKROOM1!AP31,"ERROR")))))))))))))))))))))))) -> 0.030225 | O17: INTEREST WITH NO CONVERSION: | R17: 0.06
P18: T | Q18: =R16 -> 2 | R18: =R16*R15 -> 4
P19: T+1 | Q19: =Q18+1 -> 3 | R19: =Q19*R15 -> 6
P20: T-1 | Q20: =Q18-1 -> 1 | R20: =Q20*R15 -> 2
M26: ARREARS | R26: IN ADVANCE
M27: Installment | P27: =((R11*R14)/(1-(1+R14)^(-R15*R13))) -> 25259.246 | R27: Installment | U27: =((R11*R14)/((1+R14)*(1-(1+R14)^(-R15*R13)))) -> 23829.477
M28: Loan amount | P28: =((R12*(1-(1+R14)^(-BACKROOM1!AM38))/(R14))) -> 98973.659 | R28: Loan Amount | U28: =((R12*(1+R14)*(1-(1+R14)^(-R13*R15)))/R14) -> 104912.08
M29: Balance Immediately after T | P29: =((R11*(1+R14)^R18)-((R12*((1+R14)^(R18)-1))/R14)) -> 271873.08 | R29: Balance Immediately after T | U29: =(R11*(1+R14)^(R18))-((R12*(1+R14)*(((1+R14)^(R18)-1))/R14)) -> 269248.31
M30: Interest Comp of payment (T+1) | P30: =((BACKROOM1!AQ19-R12)*(1+R14)^(R18)+R12) -> 16312.385 | R30: Interest Comp of payment (T+1) | U30: =U29*R14 -> 16154.899
M31: Capital Comp of payment (T+1) | P31: =((R12-P30)) -> -6312.3848 | R31: Capital Comp of payment (T+1) | U31: =R12-U30 -> -6154.8986
M32: Number of payments needed | P32: =ROUNDUP(-LN(1-(R11*R14)/R12)/LN(1+R14),0) -> #NUM! | R32: Number of payments needed | U32: =ROUNDUP(-LN(1-(R11*R14)/R12)/LN(1+R14),0) -> #NUM!
M33: Value of Last Payment | P33: =((R11*(1+R14)^(P32-1)-((R12*((1+R14)^(P32-1)-1))/R14))*(1+R14)) -> #NUM! | R33: Value of Last Payment | U33: =(R11*(1+R14)^(U32-1))-((R12*(1+R14)*((1+R14)^(U32-1)-1))/R14) -> #NUM!
M34: Capital paid during a certain period(T) | P34: =BACKROOM1!AM44-BACKROOM1!AN44 -> -11573.08
M35: Interest paid during certain period(T) | P35: =((BACKROOM1!AM39)*(BACKROOM1!AM41)+BACKROOM1!AM42)-((BACKROOM1!AM39)*(BACKROOM1!AN41)+BACKROOM1!AN42) -> 31573.08
M36: Total Interest Paid | P36: =((R13*R15)*R12)-R11 -> -95369.863 | R36: Total Interest Paid | U36: =(R12*(R15*R13)-R11) -> -95369.863
M37: Balance after T+1 | P37: =R13*P33-R12 -> #NUM!

Sheet 5. INCREASING ANNUITIES
H7: GIVEN | I7: INPUTS
H8: INTEREST | I8: 0.02
H9: PAYMENT | I9: 10000
H10: N(YEARS) | I10: 10
H11: P(PERIOD) | I11: 4
H12: K(LEVEL) | I12: 4
H13: M | I13: 10
H14: j(inflation) | I14: 0.05
H15: PV | I15: 400000
H16: FV | I16: 800000
D21: EVERY K'th PAYMENT INCREASING | J21: EVERY NEXT PAYMENT INCREASING
D22: ARREARS | G22: ADVANCE | J22: ARREARS | M22: ADVANCE
D23: INSTALLMENT (GIVEN FV) | E23: =(I16/(BACKROOM1!AY7/BACKROOM1!AZ7))/(((1+I8)^(I12)-1)/I8) -> 10869.557 | G23: =((I16/(BACKROOM1!AY7/BACKROOM1!AZ7))*I8)/((1+I8)*((1+I8)^I12-1)) -> 10656.428 | J23: INSTALLMENT(GIVEN FV) | K23: =I16/(((1+I8)^(I10*I11)-(1+I14)^(I11*I10))/(I8-I14)) -> 4966.9398 | M23: =(I16/(1+I8))/(((1+I8)^(I10*I11)-(1+I14)^(I11*I10))/(I8-I14)) -> 4869.5488
D24: INSTALLMENT (GIVEN PV) | E24: =(((I15*((1+I8)^(I12*I13)))/(BACKROOM1!AY7/BACKROOM1!AZ7))*I8)/((1+I8)^(I12)-1) -> 12000.206 | G24: =(((I15*(1+I8)^(I12*I13))/(BACKROOM1!AY7/BACKROOM1!AZ7))*I8)/((1+I8)*((1+I8)^(I12)-1)) -> 11764.908 | J24: INSTALLMENT(GIVEN PV) | K24: =(I15*(1+I8)^(I11*I10)*(I8-I14))/((1+I8)^(I11*I10)-(1+I14)^(I11*I10)) -> 5483.6 | M24: =((I15*(1+I8)^(I11*I10)))/(1+I8)/(((1+I8)^(I10*I11)-(1+I14)^(I11*I10))/(I8-I14)) -> 5376.0785
D25: FUTURE VALUE | E25: =BACKROOM1!AX7*(BACKROOM1!AY7/BACKROOM1!AZ7) -> 736000.57 | G25: =BACKROOM1!AX8*(BACKROOM1!AY7/BACKROOM1!AZ7) -> 750720.58 | J25: FUTURE VALUE | K25: =(I9*((1+I8)^(I11*I10)-(1+I14)^(I11*I10)))/(I8-I14) -> 1610649.7 | M25: =(I9*(1+I8))*(((1+I8)^(I10*I11)-(1+I14)^(I11*I10))/(I8-I14)) -> 1642862.7
D26: PRESENT VALUE | E26: =E25/((1+I8)^(I13*I12)) -> 333327.6 | G26: =G25/((1+I8)^(I12*I13)) -> 339994.15 | J26: PRESENT VALUE | K26: =(K25)/(1+I8)^(I10*I11) -> 729447.8 | M26: =M25/(1+I8)^(I11*I10) -> 744036.76
D33: DETERMINING THE RELATIONSHIP BETWEEN INVESTMENTS AND WITHDRAWELS
D35: From | F35: To | I35: GIVEN | J35: Investment info | K35: Withdrawal info | M35: OUTPUT
D36: Interest | E36: 0.09 | I36: Single investment | J36: 15000 | K36: 4000 | M36: The value of the first withdrawals | N36: =BACKROOM1!BM12 -> 41142.872
D37: Period | E37: 12 | F37: Period | G37: 12 | I37: Interest Rate (i) | J37: =G41 -> 0.0075 | K37: =J37 -> 0.0075 | M37: The future value of the withdrawals | N37: =BACKROOM1!BK18 -> 42651412
D38: Type | E38: nominal | F38: Type | G38: Effective periodic | I38: Inflation Rate (j) | J38: 0.06 | K38: =J38 -> 0.06 | M38: The present value of the withdrawals | N38: =BACKROOM1!BK19 -> 7097742.8
D39: Years | E39: 1 | F39: Years | G39: 1 | I39: Period (p) | J39: 12 | K39: 12 | M39: The future value of the initial investment | N39: =BACKROOM1!BM5 -> 541648.53
I40: Years (n) | J40: 40 | K40: 40 | M40: The value of the first payment | N40: =BACKROOM1!BK20 -> 686.19949
F41: Converted Rate | G41: =IF(AND(E38=BACKROOM1!BK34,G38=BACKROOM1!BL33),BACKROOM1!BL34,IF(AND(E38=BACKROOM1!BK34,G38=BACKROOM1!BM33),BACKROOM1!BM34,IF(AND(E38=BACKROOM1!BK34,G38=BACKROOM1!BN33),BACKROOM1!BN34,IF(AND(E38=BACKROOM1!BK34,G38=BACKROOM1!BO33),BACKROOM1!BO34,IF(AND(E38=BACKROOM1!BK35,G38=BACKROOM1!BL33),BACKROOM1!BL35,IF(AND(E38=BACKROOM1!BK35,G38=BACKROOM1!BM33),BACKROOM1!BM35,IF(AND(E38=BACKROOM1!BK35,G38=BACKROOM1!BN33),BACKROOM1!BN35,IF(AND(E38=BACKROOM1!BK35,G38=BACKROOM1!BO33),BACKROOM1!BO35,IF(AND(E38=BACKROOM1!BK36,G38=BACKROOM1!BL33),BACKROOM1!BL36,IF(AND(E38=BACKROOM1!BK36,G38=BACKROOM1!BM33),BACKROOM1!BM36,IF(AND(E38=BACKROOM1!BK36,G38=BACKROOM1!BN33),BACKROOM1!BN36,IF(AND(E38=BACKROOM1!BK36,G38=BACKROOM1!BO33),BACKROOM1!BO36,IF(AND(E38=BACKROOM1!BK37,G38=BACKROOM1!BL33),BACKROOM1!BL37,IF(AND(E38=BACKROOM1!BK37,G38=BACKROOM1!BM33),BACKROOM1!BM37,IF(AND(E38=BACKROOM1!BK37,G38=BACKROOM1!BN33),BACKROOM1!BN37,IF(AND(E38=BACKROOM1!BK37,G38=BACKROOM1!BO33),BACKROOM1!BO37,IF(AND(E38=BACKROOM1!BK38,G38=BACKROOM1!BL33),BACKROOM1!BL38,IF(AND(E38=BACKROOM1!BK38,G38=BACKROOM1!BM33),BACKROOM1!BM38,IF(AND(E38=BACKROOM1!BK38,G38=BACKROOM1!BN33),BACKROOM1!BN38,IF(AND(E38=BACKROOM1!BK38,G38=BACKROOM1!BO33),BACKROOM1!BO38,IF(AND(E38=BACKROOM1!BK34,G38=BACKROOM1!BP33),BACKROOM1!BP34,IF(AND(E38=BACKROOM1!BK35,G38=BACKROOM1!BP33),BACKROOM1!BP35,IF(AND(E38=BACKROOM1!BK36,G38=BACKROOM1!BP33),BACKROOM1!BP36,IF(AND(E38=BACKROOM1!BK37,G38=BACKROOM1!BP33),BACKROOM1!BP37,"ERROR")))))))))))))))))))))))) -> 0.0075 | I41: k | J41: 12 | K41: 12
I42: m | J42: 40 | K42: 20

Sheet TEB
O1: COUNTRY | P1: COMPANY | Q1: EXCHANGEMARKET | R1: RATE/share
O2: SouthAfrica | P2: Naspers | Q2: JSE | R2: 20
G3: Based on Exchange Market | O3: SouthAfrica | P3: MTN Group | Q3: JSE | R3: 25
G4: ExchangeMarket | H4: Company | I4: Rate | O4: SouthAfrica | P4: Sasol | Q4: JSE | R4: 18
G5: SSE | H5: Huawei | I5: 29 | O5: SouthAfrica | P5: ShopriteHoldings | Q5: JSE | R5: 22
O6: SouthAfrica | P6: AngloAmerican | Q6: JSE | R6: 19
G7: Purchase Amount: | I7: 10 | O7: SouthAfrica | P7: DiscoveryLimited | Q7: JSE | R7: 14
G8: Total Cost: | I8: =I7*I5 -> 290 | O8: SouthAfrica | P8: StandardBankGroup | Q8: JSE | R8: 16
G9: Equivalent Cost ® | I9: =I8*BACKROOM2_TEB!B23 -> 5218.666 | O9: SouthAfrica | P9: Absa Group Limited | Q9: JSE | R9: 17
O10: SouthAfrica | P10: FirstRandLimited | Q10: JSE | R10: 18
O11: SouthAfrica | P11: Sanlam | Q11: JSE | R11: 19
O12: SouthAfrica | P12: EskomHoldings | Q12: JSE | R12: 20
G13: Based on Country | O13: Germany | P13: BMW | Q13: FSE | R13: 24
G14: Country | H14: Company | I14: Rate | O14: Germany | P14: MercedesBenz | Q14: FSE | R14: 31
G15: China | H15: Huawei | I15: 29 | O15: USA | P15: Apple | Q15: Nasdaq | R15: 12
O16: USA | P16: Amazon | Q16: Nasdaq | R16: 19
G17: Purchase amount: | I17: 6 | O17: USA | P17: Facebook | Q17: Nasdaq | R17: 34
G18: Total Cost: | I18: =I17*I15 -> 174 | O18: USA | P18: Google | Q18: Nasdaq | R18: 29
G19: Equivalent Cost ®: | I19: =I18*BACKROOM2_TEB!B23 -> 3131.1996 | O19: USA | P19: Intel | Q19: Nasdaq | R19: 32
O20: USA | P20: Microsoft | Q20: Nasdaq | R20: 34
O21: USA | P21: Oracle | Q21: Nasdaq | R21: 34
O22: USA | P22: Visa | Q22: Nasdaq | R22: 32
G23: Value of share after n years | O23: USA | P23: CiscoSystems | Q23: Nasdaq | R23: 21
O24: USA | P24: Dell | Q24: Nasdaq | R24: 25
G25: n(number of years) | I25: 5 | O25: USA | P25: HP | Q25: Nasdaq | R25: 26
G26: FV | I26: =IF(AND(G15=BACKROOM2_TEB!A28),TEB!I19*(1+BACKROOM2_TEB!C28)^(TEB!I25),IF(AND(G15=BACKROOM2_TEB!A29),TEB!I19*(1+BACKROOM2_TEB!C29)^(TEB!I25),IF(AND(G15=BACKROOM2_TEB!A30),TEB!I19*(1+BACKROOM2_TEB!C30)^(TEB!I25),IF(AND(TEB!G15=BACKROOM2_TEB!A31),TEB!I19*(1+BACKROOM2_TEB!C31)^(TEB!I25),IF(AND(TEB!G15=BACKROOM2_TEB!A32),TEB!I19*(1+BACKROOM2_TEB!C32)^(TEB!I25),IF(AND(TEB!G15=BACKROOM2_TEB!A33),TEB!I19*(1+BACKROOM2_TEB!C33)^(TEB!I25),IF(AND(TEB!G15=BACKROOM2_TEB!A34),TEB!I19*(1+BACKROOM2_TEB!C34)^(TEB!I25),IF(AND(TEB!G15=BACKROOM2_TEB!A35),TEB!I19*(1+BACKROOM2_TEB!C35)^(TEB!I25),"")))))))) -> 5527.9438 | O26: Japan | P26: Toyota | Q26: TSE | R26: 40
O27: Japan | P27: Nissan | Q27: TSE | R27: 12
O28: Japan | P28: Konami | Q28: TSE | R28: 27
O29: Japan | P29: Subaru | Q29: TSE | R29: 10
O30: Japan | P30: Honda | Q30: TSE | R30: 19
O31: Japan | P31: Sony | Q31: TSE | R31: 18
O32: Russia | P32: Gazprom | Q32: MOEX | R32: 15
O33: Russia | P33: Rosneft | Q33: MOEX | R33: 36
O34: Russia | P34: Lukoil | Q34: MOEX | R34: 25
O35: Russia | P35: Sberbank | Q35: MOEX | R35: 31
O36: Russia | P36: Rostelecom | Q36: MOEX | R36: 29
O37: Brazil | P37: Petrobras | Q37: BM | R37: 19
O38: Brazil | P38: BancodoBrasil | Q38: BM | R38: 32
... O51: UK | P51: BritishAmericanTobacco | Q51: LSE | R51: 12

Sheet BACKROOM2_TEB
A1: SouthAfrica | B1: Germany | C1: USA | D1: Japan | E1: Russia | F1: Brazil | G1: China | H1: UK | K1: JSE | L1: FSE | M1: Nasdaq | N1: TSE | O1: MOEX | P1: BM | Q1: SSE | R1: LSE
A2: Naspers | B2: BMW | C2: Apple | D2: Toyota | E2: Gazprom | F2: Petrobras | G2: AlibabaGroup | H2: HSBCHoldings | K2: Naspers | L2: BMW | M2: Apple | N2: Toyota | O2: Gazprom | P2: Petrobras | Q2: AlibabaGroup | R2: HSBCHoldings
A3: MTN Group | B3: MercedesBenz | C3: Amazon | D3: Nissan | E3: Rosneft | F3: BancodoBrasil | G3: TencentHoldings | H3: Shell | K3: MTN Group | L3: MercedesBenz | M3: Amazon | N3: Nissan | O3: Rosneft | P3: BancodoBrasil | Q3: TencentHoldings | R3: Shell
A4: Sasol | C4: Facebook | D4: Konami | E4: Lukoil | F4: ItaúUnibanco | G4: Huawei | H4: BP | K4: Sasol | M4: Facebook | N4: Konami | O4: Lukoil | P4: ItaúUnibanco | Q4: Huawei | R4: BP
A5: ShopriteHoldings | C5: Google | D5: Subaru | E5: Sberbank | F5: Vale | G5: ChinaConstructionBank | H5: GlaxoSmithKline | K5: ShopriteHoldings | M5: Google | N5: Subaru | O5: Sberbank | P5: Vale | Q5: ChinaConstructionBank | R5: GlaxoSmithKline
A6: AngloAmerican | C6: Intel | D6: Honda | E6: Rostelecom | F6: JBS | G6: Industrial&CommercialBankofChina | H6: BritishAmericanTobacco | K6: AngloAmerican | M6: Intel | N6: Honda | O6: Rostelecom | P6: JBS | Q6: Industrial&CommercialBankofChina | R6: BritishAmericanTobacco
A7: DiscoveryLimited | C7: Microsoft | D7: Sony | K7: DiscoveryLimited | M7: Microsoft | N7: Sony
A8: StandardBankGroup | C8: Oracle | K8: StandardBankGroup | M8: Oracle
A9: Absa Group Limited | C9: Visa | K9: Absa Group Limited | M9: Visa
A10: FirstRandLimited | C10: CiscoSystems | K10: FirstRandLimited | M10: CiscoSystems
A11: Sanlam | C11: Dell | K11: Sanlam | M11: Dell
A12: EskomHoldings | C12: HP | K12: EskomHoldings | M12: HP
A18: Naspers | B18: MTN Group | C18: Sasol | D18: ShopriteHoldings | E18: AngloAmerican | F18: DiscoveryLimited | G18: StandardBankGroup | H18: Absa Group Limited | I18: FirstRandLimited | J18: Sanlam | K18: EskomHoldings | L18: BMW | M18: MercedesBenz | N18: Apple | O18: Amazon | P18: Facebook | Q18: Google | R18: Intel | S18: Microsoft | T18: Oracle | U18: Visa | V18: CiscoSystems | W18: Dell | X18: HP | Y18: Toyota | Z18: Nissan | AA18: Konami | AB18: Subaru | AC18: Honda | AD18: Sony | AE18: Gazprom | AF18: Rosneft | AG18: Lukoil | AH18: Sberbank | AI18: Rostelecom | AJ18: Petrobras | AK18: BancodoBrasil | AL18: ItaúUnibanco | AM18: Vale | AN18: JBS | AO18: AlibabaGroup | AP18: TencentHoldings | AQ18: Huawei | AR18: ChinaConstructionBank | AS18: Industrial&CommercialBankofChina | AT18: HSBCHoldings | AU18: Shell | AV18: BP | AW18: GlaxoSmithKline | AX18: BritishAmericanTobacco
A19: 20 | B19: 25 | C19: 18 | D19: 22 | E19: 19 | F19: 14 | G19: 16 | H19: 17 | I19: 18 | J19: 19 | K19: 20 | L19: 24 | M19: 31 | N19: 12 | O19: 19 | P19: 34 | Q19: 29 | R19: 32 | S19: 34 | T19: 34 | U19: 32 | V19: 21 | W19: 25 | X19: 26 | Y19: 40 | Z19: 12 | AA19: 27 | AB19: 10 | AC19: 19 | AD19: 18 | AE19: 15 | AF19: 36 | AG19: 25 | AH19: 31 | AI19: 29 | AJ19: 19 | AK19: 32 | AL19: 12 | AM19: 9 | AN19: 6 | AO19: 12 | AP19: 22 | AQ19: 29 | AR19: 35 | AS19: 23 | AT19: 40 | AU19: 23 | AV19: 18 | AW19: 31 | AX19: 12
A22: CURRENT USD/ZAR EXCHANGE RATE
A23: #VALUE! | B23: {=_FV(A23,"Price")} -> 17.9954
A27: COUNTRY | B27: AVERAGE ANNUAL INTEREST RATE (>15yrs) | C27: INTEREST RATE
A28: SouthAfrica | B28: 20-25% | C28: =RAND()*0.05+0.2 -> 0.23877546
A29: Germany | B29: 20-25% | C29: =RAND()*0.05+0.2 -> 0.24516292
A30: USA | B30: 7-10% | C30: =RAND()*0.03+0.07 -> 0.085570302
A31: Japan | B31: 20-23% | C31: =RAND()*0.03+0.2 -> 0.20988617
A32: Russia | B32: 0-2% | C32: =RAND()*0.02+0 -> 0.017661116
A33: Brazil | B33: 15-20% | C33: =RAND()*0.05+0.15 -> 0.1649794
A34: China | B34: 10-15% | C34: =RAND()*0.05+0.1 -> 0.12039348
A35: UK | B35: 10-15% | C35: =RAND()*0.05+0.1 -> 0.10034412

Sheet BACKROOM1
A1: INTEREST CONVERTER | I1: SINGLE INVESTMENTS | S1: ANNUITIES | AF1: LOANS | AU1: INCREASING ANNUITIES
A2: From | C2: To
A3: Interest (i) | B3: ='1. RATE CONVERTER'!P11 -> 0.08 | C3: Interest (i) | D3: =(('1. RATE CONVERTER'!R11)) -> 0
A4: Period (p) | B4: ='1. RATE CONVERTER'!P12 -> 4 | C4: periods (p) | D4: ='1. RATE CONVERTER'!R12 -> 1 | K4: Input | BJ4: Single investments
A5: Years (n) | B5: =(('1. RATE CONVERTER'!P14)) -> 6 | C5: years (n) | D5: =(('1. RATE CONVERTER'!R14)) -> 6 | K5: From | M5: To | BJ5: pv | BK5: ='5. INCREASING ANNUITIES'!J36 -> 15000 | BL5: fv | BM5: =BK5*(1+BK7)^(BK8*BK9) -> 541648.53
K6: Interest (i) | L6: ='2. SINGLE INVESTMENTS'!C14 -> 0.07 | M6: Interest (i) | N6: =(('2. SINGLE INVESTMENTS'!E14)) -> 0 | Z6: Column2 | AA6: Column3 | AB6: Column4 | AX6: part 1 | AY6: part 2 | AZ6: part 3 | BJ6: fv | BK6: 52422.662
A7: Grid | B7: Effective annual | C7: Effective periodic | D7: Nominal | E7: Simple | F7: continous | K7: Period (p) | L7: ='2. SINGLE INVESTMENTS'!C15 -> 12 | M7: periods (p) | N7: ='2. SINGLE INVESTMENTS'!E15 -> 4 | Y7: Input | AX7: =('5. INCREASING ANNUITIES'!I9*((1+'5. INCREASING ANNUITIES'!I8)^('5. INCREASING ANNUITIES'!I12)-1))/'5. INCREASING ANNUITIES'!I8 -> 41216.08 | AY7: =((1+'5. INCREASING ANNUITIES'!I8)^('5. INCREASING ANNUITIES'!I12*'5. INCREASING ANNUITIES'!I13)-(1+'5. INCREASING ANNUITIES'!I14)^'5. INCREASING ANNUITIES'!I13) -> 0.57914504 | AZ7: =((1+'5. INCREASING ANNUITIES'!I8)^('5. INCREASING ANNUITIES'!I12)-(1+'5. INCREASING ANNUITIES'!I14)) -> 0.03243216 | BJ7: i | BK7: ='5. INCREASING ANNUITIES'!J37 -> 0.0075
A8: effective annual | B8: =B3 -> 0.08 | C8: =((1+B3)^(1/D4))-1 -> 0.08 | D8: =(((1+B3)^(1/D4))-1)*D4 -> 0.08 | E8: =B3/(D5*D4) -> 0.013333333 | F8: =LN(1+B3)^(B5) -> 2.0779046e-07 | K8: Years (n) | L8: =(('2. SINGLE INVESTMENTS'!C17)) -> 1 | M8: years (n) | N8: =('2. SINGLE INVESTMENTS'!E17) -> 1 | Y8: From | AA8: To | AN8: To | AX8: =('5. INCREASING ANNUITIES'!I9*(1+'5. INCREASING ANNUITIES'!I8)*((1+'5. INCREASING ANNUITIES'!I8)^('5. INCREASING ANNUITIES'!I12)-1))/'5. INCREASING ANNUITIES'!I8 -> 42040.402 | BJ8: n | BK8: ='5. INCREASING ANNUITIES'!J40 -> 40
A9: effective periodic | B9: =((1+B3)^(B4))-1 -> 0.36048896 | C9: =((1+B3)^(B4/D4))-1 -> 0.36048896 | D9: =((1+B3)^(B4/D4)-1)*D4 -> 0.36048896 | E9: =((1+B3)^(B4)-1)/D4 -> 0.36048896 | F9: =LN((1+B3)^(B4)) -> 0.30784416 | W9: ='3. ANNUITIES'!P29 -> 150.32355 | Y9: Interest (i) | Z9: ='3. ANNUITIES'!J13 -> 0.08 | AA9: Interest (i) | AB9: =(('3. ANNUITIES'!L13)) -> 0 | BJ9: p | BK9: ='5. INCREASING ANNUITIES'!J39 -> 12
A10: nominal | B10: =((1+B3/B4)^(12))-1 -> 0.26824179 | C10: =((1+B3/B4)^(B4/D4))-1 -> 0.08243216 | D10: =((1+B3/B4)^(B4/D4)-1)*D4 -> 0.08243216 | E10: =((1+B3/B4)^(B4)-1)/D4 -> 0.08243216 | F10: =LN(1+B3)^(B5*B4) -> 1.8642426e-27 | K10: Grid | L10: Effective annual | M10: Effective periodic | N10: Nominal | O10: Simple | P10: continous | Y10: Period (p) | Z10: ='3. ANNUITIES'!J14 -> 1 | AA10: periods (p) | AB10: ='3. ANNUITIES'!L14 -> 12
A11: simple | B11: =((1+B3*B4))-1 -> 0.32 | C11: =((1+B3*B4)^(1/D4)-1) -> 0.32 | D11: =((1+B3*B4)^(1/D4)-1)*D4 -> 0.32 | E11: =((1+$B3*$B4)-1)/D4 -> 0.32 | F11: =LN(1+B5*B3*B4) -> 1.0715836 | K11: effective annual | L11: =L6 -> 0.07 | M11: =((1+L6)^(1/N7))-1 -> 0.017058525 | N11: =(((1+L6)^(1/N7))-1)*N7 -> 0.0682341 | O11: =L6/(N8*N7) -> 0.0175 | P11: =LN(1+L6)^(L8) -> 0.067658648 | Y11: Years (n) | Z11: =(('3. ANNUITIES'!J16)) -> 1 | AA11: years (n) | AB11: =(('3. ANNUITIES'!L16)) -> 1 | BJ11: Accumulated amount with j
A12: continous | B12: =A13^(B3/(D5*D4))-1 -> 0.013422619 | C12: =A13^(B3/(D4*D5))-1 -> 0.013422619 | D12: =(A13^(B3/(D4*D5))-1)*D4 -> 0.013422619 | E12: =(A13^(B3)-1)/(D5*D4) -> 0.013881178 | K12: effective periodic | L12: =((1+L6)^(L7))-1 -> 1.2521916 | M12: =((1+L6)^(L7/N7))-1 -> 0.225043 | N12: =((1+L6)^(L7/N7)-1)*N7 -> 0.900172 | O12: =((1+L6)^(L7)-1)/N7 -> 0.3130479 | P12: =LN((1+L6)^(L7)) -> 0.81190378 | U12: =(('3. ANNUITIES'!Q12*'3. ANNUITIES'!Q8)/'3. ANNUITIES'!Q7*(1+'3. ANNUITIES'!Q8))+1 -> 1.0272045 | BJ12: amount to adjust | BK12: ='5. INCREASING ANNUITIES'!K36 -> 4000 | BL12: the accumulated amount | BM12: =BK12*(1+BK14)^(BK13) -> 41142.872
A13: =EXP(1) -> 2.7182818 | K13: nominal | L13: =((1+L6/L7)^(12))-1 -> 0.072290081 | M13: =((1+L6/L7)^(L7/N7))-1 -> 0.017602282 | N13: =((1+L6/L7)^(L7/N7)-1)*N7 -> 0.070409127 | O13: =((1+L6/L7)^(L7)-1)/N7 -> 0.01807252 | P13: =LN((1+(L6/L7)))*(L7*L8) -> 0.069796624 | U13: =-(('3. ANNUITIES'!Q11*'3. ANNUITIES'!Q8)/'3. ANNUITIES'!Q7*(1+'3. ANNUITIES'!Q8)-1) -> 0.97856619 | Y13: Grid | Z13: Effective annual | AA13: Effective periodic | AB13: Nominal | AC13: Simple | AD13: continous | BJ13: years to inflate | BK13: ='5. INCREASING ANNUITIES'!K40 -> 40
K14: simple | L14: =((1+L6*L7))-1 -> 0.84 | M14: =((1+$L6*$L7)^(1/$N7)-1) -> 0.1646742 | N14: =((1+$L6*$L7)^(1/$N7)-1)*N7 -> 0.65869681 | O14: =((1+$L6*$L7)-1)/N7 -> 0.21 | P14: =LN(1+L8*L6*L7) -> 0.60976557 | Y14: effective annual | Z14: =Z9 -> 0.08 | AA14: =((1+Z9)^(1/AB10))-1 -> 0.0064340301 | AB14: =(((1+Z9)^(1/AB10))-1)*AB10 -> 0.077208361 | AC14: =Z9/(AB11*AB10) -> 0.0066666667 | AD14: =LN(1+Z9)^(Z11) -> 0.076961041 | BJ14: inflation rate(j) | BK14: ='5. INCREASING ANNUITIES'!J38 -> 0.06
K15: continous | L15: =K17^(L6/(N8*N7))-1 -> 0.017654022 | M15: =K17^(L6/(N7*N8))-1 -> 0.017654022 | N15: =(K17^(L6/(N7*N8))-1)*N7 -> 0.070616089 | O15: =(K17^(L6)-1)/(N8*N7) -> 0.018127045 | Y15: effective periodic | Z15: =((1+Z9)^(Z10))-1 -> 0.08 | AA15: =((1+Z9)^(Z10/AB10))-1 -> 0.0064340301 | AB15: =((1+Z9)^(Z10/AB10)-1)*AB10 -> 0.077208361 | AC15: =((1+Z9)^(Z10)-1)/AB10 -> 0.0066666667 | AD15: =LN((1+Z9)^(Z10)) -> 0.076961041 | AL15: {='4.LOANS'!J17:K17} -> 0.030225 | AM15: 0
Y16: nominal | Z16: =((1+Z9/Z10)^(12))-1 -> 1.5181701 | AA16: =((1+Z9/Z10)^(Z10/AB10))-1 -> 0.0064340301 | AB16: =((1+Z9/Z10)^(Z10/AB10)-1)*AB10 -> 0.077208361 | AC16: =((1+Z9/Z10)^(Z10)-1)/AB10 -> 0.0066666667 | AD16: =LN((1+(Z9/Z10)))*(Z10*Z11) -> 0.076961041 | AL16: ='4.LOANS'!R17 -> 0.06
K17: =EXP(1) -> 2.7182818 | Y17: simple | Z17: =((1+Z9*Z10))-1 -> 0.08 | AA17: =((1+$Z9*$Z10)^(1/$AB10)-1) -> 0.0064340301 | AB17: =((1+$Z9*$Z10)^(1/$AB10)-1)*AB10 -> 0.077208361 | AC17: =((1+$Z9*$Z10)-1)/AB10 -> 0.0066666667 | AD17: =LN(1+Z11*Z9*Z10) -> 0.076961041 | BJ17: solving for a part of x | BK17: =(((1+('5. INCREASING ANNUITIES'!J37))^('5. INCREASING ANNUITIES'!J41)-1)/('5. INCREASING ANNUITIES'!J37))*((1+('5. INCREASING ANNUITIES'!J37))^('5. INCREASING ANNUITIES'!J41*'5. INCREASING ANNUITIES'!J42)-(1+'5. INCREASING ANNUITIES'!J38)^('5. INCREASING ANNUITIES'!J42))/((1+('5. INCREASING ANNUITIES'!J37))^('5. INCREASING ANNUITIES'!J41)-(1+'5. INCREASING ANNUITIES'!J38)) -> 9554.2104
Y18: continous | Z18: =Y20^(Z9/(AB11*AB10))-1 -> 0.0066889384 | AA18: =Y20^(Z9/(AB10*AB11))-1 -> 0.0066889384 | AB18: =(Y20^(Z9/(AB10*AB11))-1)*AB10 -> 0.08026726 | AC18: =(Y20^(Z9)-1)/(AB11*AB10) -> 0.006940589 | BJ18: fv of withdrawal | BK18: =BACKROOM1!BM12*(((1+'5. INCREASING ANNUITIES'!K37)^('5. INCREASING ANNUITIES'!K41)-1)/'5. INCREASING ANNUITIES'!K37)*((1+'5. INCREASING ANNUITIES'!K37)^('5. INCREASING ANNUITIES'!K42*'5. INCREASING ANNUITIES'!K41)-(1+'5. INCREASING ANNUITIES'!K38)^('5. INCREASING ANNUITIES'!K42))/((1+'5. INCREASING ANNUITIES'!K37)^('5. INCREASING ANNUITIES'!K41)-(1+'5. INCREASING ANNUITIES'!K38)) -> 42651412
K19: ='2. SINGLE INVESTMENTS'!K11 -> 0.1 | AQ19: ='4.LOANS'!R11*'4.LOANS'!R14 -> 15000 | BJ19: pv of withdrawal | BK19: =BACKROOM1!BM12*(((1+'5. INCREASING ANNUITIES'!K37)^('5. INCREASING ANNUITIES'!K41)-1)/'5. INCREASING ANNUITIES'!K37)*((1+'5. INCREASING ANNUITIES'!K37)^('5. INCREASING ANNUITIES'!K42*'5. INCREASING ANNUITIES'!K41)-(1+'5. INCREASING ANNUITIES'!K38)^('5. INCREASING ANNUITIES'!K42))/((1+'5. INCREASING ANNUITIES'!K37)^('5. INCREASING ANNUITIES'!K41)-(1+'5. INCREASING ANNUITIES'!K38))/(1+'5. INCREASING ANNUITIES'!K37)^('5. INCREASING ANNUITIES'!K41*'5. INCREASING ANNUITIES'!K42) -> 7097742.8
K20: ='2. SINGLE INVESTMENTS'!E19 -> 0.225043 | Y20: =EXP(1) -> 2.7182818 | AL20: Column2 | AM20: Column3 | AN20: Column4 | BJ20: x | BK20: =(BK19-BACKROOM1!BM5)/BK17 -> 686.19949
AK21: Input
AK22: From | AM22: To
K23: INTEREST TYPE | L23: FUTURE VALUE | M23: PRESENT VALUE | N23: YEARS | O23: INTEREST | P23: INTEREST EARNED | Y23: CONVERSIONS | AK23: Interest (i) | AL23: ='4.LOANS'!H13 -> 0.06 | AM23: Interest (i) | AN23: =(('4.LOANS'!J13)) -> 0
K24: SIMPLE | L24: ='2. SINGLE INVESTMENTS'!Z4*(1+('2. SINGLE INVESTMENTS'!Z5*'2. SINGLE INVESTMENTS'!Z6*'2. SINGLE INVESTMENTS'!Z7)) -> 18000 | M24: ='2. SINGLE INVESTMENTS'!Z3/(1+'2. SINGLE INVESTMENTS'!Z5*'2. SINGLE INVESTMENTS'!Z6*'2. SINGLE INVESTMENTS'!Z7) -> 1111.1111 | N24: =(('2. SINGLE INVESTMENTS'!Z3/'2. SINGLE INVESTMENTS'!Z4)-1)/('2. SINGLE INVESTMENTS'!Z5*'2. SINGLE INVESTMENTS'!Z7) -> 5 | O24: =(('2. SINGLE INVESTMENTS'!Z3/'2. SINGLE INVESTMENTS'!Z4)-1)/('2. SINGLE INVESTMENTS'!Z6*'2. SINGLE INVESTMENTS'!Z7) -> 0.05 | P24: =L24-M24 -> 16888.889 | Y24: ='3. ANNUITIES'!Q13 -> 0.07 | Z24: ='3. ANNUITIES'!L17 -> 0.0066889384 | AK24: Period (p) | AL24: ='4.LOANS'!H14 -> 4 | AM24: periods (p) | AN24: ='4.LOANS'!J14 -> 2
K25: EFFECTIVE PERIODIC | L25: ='2. SINGLE INVESTMENTS'!Z4*(1+'2. SINGLE INVESTMENTS'!Z5)^('2. SINGLE INVESTMENTS'!Z7*'2. SINGLE INVESTMENTS'!Z6) -> 4096800.4 | M25: ='2. SINGLE INVESTMENTS'!Z3/(1+'2. SINGLE INVESTMENTS'!Z5)^('2. SINGLE INVESTMENTS'!Z7*'2. SINGLE INVESTMENTS'!Z6) -> 4.8818585 | N25: =((LOG('2. SINGLE INVESTMENTS'!Z3/'2. SINGLE INVESTMENTS'!Z4))/(LOG(1+'2. SINGLE INVESTMENTS'!Z5)))/'2. SINGLE INVESTMENTS'!Z7 -> 2.1107896 | O25: =(('2. SINGLE INVESTMENTS'!Z3/'2. SINGLE INVESTMENTS'!Z4)^(1/('2. SINGLE INVESTMENTS'!Z6*'2. SINGLE INVESTMENTS'!Z7)))-1 -> 0.020321704 | P25: =L25-M25 -> 4096795.5 | U25: =-((('3. ANNUITIES'!Q11*'3. ANNUITIES'!Q8)/'3. ANNUITIES'!Q7)-1) -> 0.97899061 | V25: =-'3. ANNUITIES'!Q9*'3. ANNUITIES'!Q10 -> -60 | AK25: Years (n) | AL25: =(('4.LOANS'!H16)) -> 6 | AM25: years (n) | AN25: =(('4.LOANS'!J16)) -> 6
K26: EFFECTIVE ANNUAL | L26: ='2. SINGLE INVESTMENTS'!Z4*((1+'2. SINGLE INVESTMENTS'!Z5)^('2. SINGLE INVESTMENTS'!Z6)) -> 5187.4849 | M26: =('2. SINGLE INVESTMENTS'!Z3)/(1+'2. SINGLE INVESTMENTS'!Z5)^('2. SINGLE INVESTMENTS'!Z6) -> 3855.4329 | N26: =(LOG('2. SINGLE INVESTMENTS'!Z3/'2. SINGLE INVESTMENTS'!Z4))/(LOG(1+'2. SINGLE INVESTMENTS'!Z5)) -> 16.886317 | O26: =('2. SINGLE INVESTMENTS'!Z3/'2. SINGLE INVESTMENTS'!Z4)^(1/'2. SINGLE INVESTMENTS'!Z6*'2. SINGLE INVESTMENTS'!Z7)-1 -> 2.6238983 | P26: =L26-M26 -> 1332.052 | U26: =('3. ANNUITIES'!Q12*'3. ANNUITIES'!Q8)/'3. ANNUITIES'!Q7 -> 0.026665769
K27: NOMINAL | L27: ='2. SINGLE INVESTMENTS'!Z4*(1+('2. SINGLE INVESTMENTS'!Z5/'2. SINGLE INVESTMENTS'!Z7))^('2. SINGLE INVESTMENTS'!Z6*'2. SINGLE INVESTMENTS'!Z7) -> 5402.9699 | M27: ='2. SINGLE INVESTMENTS'!Z3/((1+('2. SINGLE INVESTMENTS'!Z5/'2. SINGLE INVESTMENTS'!Z7))^('2. SINGLE INVESTMENTS'!Z6*'2. SINGLE INVESTMENTS'!Z7)) -> 3701.6679 | N27: =((LOG('2. SINGLE INVESTMENTS'!Z3/'2. SINGLE INVESTMENTS'!Z4))/(LOG(1+('2. SINGLE INVESTMENTS'!Z5/'2. SINGLE INVESTMENTS'!Z7))))/'2. SINGLE INVESTMENTS'!Z7 -> 16.194761 | O27: =(('2. SINGLE INVESTMENTS'!Z3/'2. SINGLE INVESTMENTS'!Z4)^(1/('2. SINGLE INVESTMENTS'!Z6*'2. SINGLE INVESTMENTS'!Z7))-1)*'2. SINGLE INVESTMENTS'!Z7 -> 0.16257363 | P27: =L27-M27 -> 1701.302 | AK27: Grid | AL27: Effective annual | AM27: Effective periodic | AN27: Nominal | AO27: Simple | AP27: continous
K28: CONTINOUS | L28: =('2. SINGLE INVESTMENTS'!K7)*EXP(1)^('2. SINGLE INVESTMENTS'!K8*'2. SINGLE INVESTMENTS'!K9) -> 5436.5637 | M28: ='2. SINGLE INVESTMENTS'!K6/EXP(1)^('2. SINGLE INVESTMENTS'!K8*'2. SINGLE INVESTMENTS'!K9) -> 3678.7944 | N28: =(LN('2. SINGLE INVESTMENTS'!K6/'2. SINGLE INVESTMENTS'!K7))/'2. SINGLE INVESTMENTS'!K8 -> 16.094379 | O28: =(LN('2. SINGLE INVESTMENTS'!K6/'2. SINGLE INVESTMENTS'!K7))/'2. SINGLE INVESTMENTS'!K9 -> 0.16094379 | V28: =U26+1 -> 1.0266658 | AK28: effective annual | AL28: =AL23 -> 0.06 | AM28: =((1+AL23)^(1/AN24))-1 -> 0.029563014 | AN28: =(((1+AL23)^(1/AN24))-1)*AN24 -> 0.059126028 | AO28: =AL23/(AN25*AN24) -> 0.005 | AP28: =LN(1+AL23)^(AL25) -> 3.9140041e-08 | BK28: From | BM28: To
AK29: effective periodic | AL29: =((1+AL23)^(AL24))-1 -> 0.26247696 | AM29: =((1+AL23)^(AL24/AN24))-1 -> 0.1236 | AN29: =((1+AL23)^(AL24/AN24)-1)*AN24 -> 0.2472 | AO29: =((1+AL23)^(AL24)-1)/AN24 -> 0.13123848 | AP29: =LN((1+AL23)^(AL24)) -> 0.23307563 | BK29: Interest (i) | BL29: ='5. INCREASING ANNUITIES'!E36 -> 0.09 | BM29: Interest (i) | BN29: =(('5. INCREASING ANNUITIES'!G36)) -> 0
AK30: nominal | AL30: =((1+AL23/AL24)^(12))-1 -> 0.19561817 | AM30: =((1+AL23/AL24)^(AL24/AN24))-1 -> 0.030225 | AN30: =((1+AL23/AL24)^(AL24/AN24)-1)*AN24 -> 0.06045 | AO30: =((1+AL23/AL24)^(AL24)-1)/AN24 -> 0.030681775 | AP30: =LN((1+(AL23/AL24)))*(AL24*AL25) -> 0.3573267 | BK30: Period (p) | BL30: ='5. INCREASING ANNUITIES'!E37 -> 12 | BM30: periods (p) | BN30: ='5. INCREASING ANNUITIES'!G37 -> 12
AK31: simple | AL31: =((1+AL23*AL24))-1 -> 0.24 | AM31: =((1+$AJ23*$AJ24)^(1/$AL24)-1) -> 0 | AN31: =((1+$AJ23*$AJ24)^(1/$AL24)-1)*AN24 -> 0 | AO31: =((1+$AJ23*$AJ24)-1)/AN24 -> 0 | AP31: =LN(1+AL25*AL23*AL24) -> 0.89199804 | BK31: Years (n) | BL31: =(('5. INCREASING ANNUITIES'!E39)) -> 1 | BM31: years (n) | BN31: =(('5. INCREASING ANNUITIES'!G39)) -> 1
AK32: continous | AL32: =AK34^(AL23/(AN25*AN24))-1 -> 0.0050125209 | AM32: =AK34^(AL23/(AN24*AN25))-1 -> 0.0050125209 | AN32: =(AK34^(AL23/(AN24*AN25))-1)*AN24 -> 0.010025042 | AO32: =(AK34^(AL23)-1)/(AN25*AN24) -> 0.0051530455
BK33: Grid | BL33: Effective annual | BM33: Effective periodic | BN33: Nominal | BO33: Simple | BP33: continous
AK34: =EXP(1) -> 2.7182818 | BK34: effective annual | BL34: =BL29 -> 0.09 | BM34: =((1+BL29)^(1/BN30))-1 -> 0.0072073233 | BN34: =(((1+BL29)^(1/BN30))-1)*BN30 -> 0.08648788 | BO34: =BL29/(BN31*BN30) -> 0.0075 | BP34: =LN(1+BL29)^(BL31) -> 0.086177696
AM35: =AR8*(1+AR11)^AR14 -> 0 | BK35: effective periodic | BL35: =((1+BL29)^(BL30))-1 -> 1.8126648 | BM35: =((1+BL29)^(BL30/BN30))-1 -> 0.09 | BN35: =((1+BL29)^(BL30/BN30)-1)*BN30 -> 1.08 | BO35: =((1+BL29)^(BL30)-1)/BN30 -> 0.1510554 | BP35: =LN((1+BL29)^(BL30)) -> 1.0341324
BK36: nominal | BL36: =((1+BL29/BL30)^(12))-1 -> 0.093806898 | BM36: =((1+BL29/BL30)^(BL30/BN30))-1 -> 0.0075 | BN36: =((1+BL29/BL30)^(BL30/BN30)-1)*BN30 -> 0.09 | BO36: =((1+BL29/BL30)^(BL30)-1)/BN30 -> 0.0078172415 | BP36: =LN(1+BL29)^(BL31*BL30) -> 1.6777937e-13
BK37: simple | BL37: =((1+BL29*BL30))-1 -> 1.08 | BM37: =((1+#REF!*#REF!)^(1/$BK30)-1) -> #REF! | BN37: =((1+#REF!*#REF!)^(1/$BK30)-1)*BN30 -> #REF! | BO37: =((1+#REF!*#REF!)-1)/BN30 -> #REF! | BP37: =LN(1+BL31*BL29*BL30) -> 0.73236789
AM38: ='4.LOANS'!R15*'4.LOANS'!R13 -> 15.463014 | BK38: continous | BL38: =BK39^(BL29/(BN31*BN30))-1 -> 0.0075281954 | BM38: =BK39^(BL29/(BN30*BN31))-1 -> 0.0075281954 | BN38: =(BK39^(BL29/(BN30*BN31))-1)*BN30 -> 0.090338345 | BO38: =(BK39^(BL29)-1)/(BN31*BN30) -> 0.007847857
AM39: ='4.LOANS'!R11*'4.LOANS'!R14-'4.LOANS'!R12 -> 5000 | AN39: NI-X | BK39: =EXP(1) -> 2.7182818
AM40: =((1+'4.LOANS'!R14)^'4.LOANS'!R18)-1 -> 0.26247696 | AN40: =((1+'4.LOANS'!R14)^'4.LOANS'!R20)-1 -> 0.1236
...
